Workbook

Sheet Corrections & Flags
A1: Base Model - Corrections & Flags
A2: Review of Financing_Model_v6_260311 (base). Same template family as Coyner Park, and it carried the same structural bugs. This copy fixes them and flags items to confirm. Changed cells are green (with a comment); flagged (unchanged) cells are orange.
A4: HEADLINE IMPACT
B5: Metric | C5: As-built (v6) | D5: Corrected | E5: Note
B6: Levered IRR | C6: 14.7% | D6: =Annual!J46 -> 0.16715309 | E6: Up slightly - only the loan-payoff fix moves it (no commission added)
B7: Levered equity multiple | C7: 1.95x | D7: =Annual!J47 -> 2.121005 | E7: Same driver
B8: Cash-on-cash (stabilized) | C8: 2.1% | D8: =Annual!J50 -> 0.022727416 | E8: Unchanged - operating-year metric
B9: Loan balance at payoff | C9: -$164,811 | D9: =Annual!O118 -> 0 | E9: Sign fix; now $0
B10: Project cost (summary block) | C10: $9,774,470 | D10: =Summary!AC11 -> 5289604.8 | E10: Removed double-count; now ties to $5.33M
A12: LEGEND
B13: Corrected cell | C13: math changed - see the cell comment
B14: Flag / note | C14: not changed - confirm or decide
B15: Key assumption | C15: original author's input cells - left as-is
A17: CORRECTIONS (math fixed in this file)
A18: # | B18: Sheet | C18: Cell(s) | D18: Category | E18: What it was | F18: What it is now | G18: Why it matters
A19: 1 | B19: Annual | C19: J117:T117 | D19: Loan payoff | E19: -X112+X116 over-repaid the loan by $164,811; ending balance was -$164,811. | F19: -(X112+X116); ending balance now $0. | G19: Sale-year cash flow was understated; corrects IRR/profit upward.
A20: 2 | B20: Summary | C20: AC10 / AC11 | D20: Project-cost double count | E20: AC10 =SUM(L22:L37) included L31 (full dev-cost subtotal); cost showed $9.77M. | F20: Now SUM(L22:L30,L33:L38); now $5.33m, ties to l39. | G20: Fixes the Threshold Cashflow (AO9) built on a doubled cost.
A21: 3 | B21: Annual | C21: M94, M95 | D21: Broken reference | E21: M94 = REF-error (only live error). M95 summed ~130 empty columns. | F21: M94 =I94-I96, M95 =I96. | G21: Removes the workbook’s only hard error. Scratch block - verify or delete; real GP metrics are H92:I96.
A22: 4 | B22: Annual | C22: K35:T35, K36:T36 | D22: Latent broken refs | E22: Pointed to Summary REF-errors / wrong cells; harmless only because loan funds in year 0. | F22: Set to 0. | G22: Prevents garbage if a later-year draw is ever modeled. J35/J36 unchanged.
A23: 5 | B23: Annual | C23: E26 | D23: Cosmetic | E23: "Total Cost/SF" divided by the NNN rate -> ~$3.6M/SF. | F23: Now E25/E5 -> ~$444/sf. | G23: Display only.
A24: 6 | B24: Summary | C24: F21 | D24: Cosmetic | E24: "Breakeven Rent" showed -$29.19 (summed only cost lines). | F24: Negated -> positive $/SF. | G24: Display only.
A26: FLAGS (no change made - confirm or decide)
A27: # | B27: Where | D27: Topic | E27: Detail | G27: What to do
B28: Where | D28: Topic | E28: Detail | G28: What to do
A29: A | B29: Summary S21 / V21 | D29: Exit commission (7%) | E29: Intentionally NOT added to the project cash flow / IRR. A broker commission is a transaction cost, not a measure of deal quality (per the direction on Coyner). Only the 1.5% cost of sale flows into the project return. | G29: Confirm. If you want a take-home number, add a Net Proceeds tab (commission + loan payoff + taxes), like Coyner v8.
A30: B | B30: Workbook | D30: Orphan tabs removed | E30: Deleted LP GP, Allen and Lists - a separate ground-up "Pole Lot" development and leftover dropdown lists, not part of this deal. Nothing live referenced them. | G30: None needed. Say the word if you want them restored.
A31: C | B31: Summary L36/L37 | D31: Circular reference | E31: Loan fees depend on total cost, which includes the fees. Resolves fine (iterative calc is on). | G31: Leave as-is; it warns only if that Excel setting is turned off.
A32: D | B32: Annual | D32: NNN opex / recoveries | E32: No taxes/insurance/CAM modeled as expenses; recoveries computed off the mgmt fee only (same template simplification as Coyner). | G32: Confirm the simplification fits the deal.
A34: Note: the 7% commission was NOT added to the project IRR here (unlike the first Coyner pass), reflecting the later direction that commission belongs in a separate take-home rather than the deal return. Ask if you want it added instead.

Sheet Summary
A1: Property Name
A2: =MID(CELL("filename",A1),FIND("]",CELL("filename",A1))+1,256) -> Summary | I2: NEED TO TIGHEN UP THE COMMISSIONS AND CLOSING COSTS VS Equity CONTRIBUTIONS
B4: Project Summary | H4: Sources & Uses | N4: Debt Financing | S4: Base Pro Forma | Z4: Summary
B5: Site | E5: Building | H5: Sources
B6: Land Acres | C6: 1 | E6: # of Buildings | F6: 1 | J6: % | K6: $/RSF | L6: $ Total | N6: Total Loan | P6: 0.75 | Q6: =L39*P6 -> 3967203.6 | U6: $/RSF | V6: Total | AB6: Project Cost | AH6: Proforma | AI6: Total | AJ6: $/RSF | AN6: Results @ 100% Financing
B7: Land SF | C7: 0 | E7: RSF | F7: =D18 -> 12000 | H7: Debt | J7: =+L7/$L$39 -> 0.75 | K7: =L7/$F$7 -> 330.6003 | L7: =Q6 -> 3967203.6 | N7: Loan Origination Fee | P7: 0.01 | Q7: =P7*Q6 -> 39672.036 | S7: Base Rent | U7: =V7/F7 -> 30 | V7: =F18 -> 360000 | AB7: Purchase Price/Land Value | AC7: =L13 -> 2000000 | AH7: Base Rent | AI7: =V7 -> 360000 | AJ7: =U7 -> 30 | AN7: Millions of project cost | AO7: =AC11/1000000 -> 5.2896047
H8: Equity | J8: =+L8/$L$39 -> 0.25 | K8: =L8/$F$7 -> 110.2001 | L8: =L39-L7 -> 1322401.2 | N8: Loan Closing Costs | P8: 0.0075 | Q8: =-P8*Q6 -> -29754.027 | S8: NNN Recoveries | V8: =Annual!K12 -> 17952.756 | AB8: Hard Costs (i.e. Const, TI) | AC8: =SUM(L16:L17,L19:L20) -> 2550000 | AH8: NNN Recoveries | AI8: =V8 -> 17952.756 | AN8: Cash Needs Per Million | AO8: 20000
H9: Total Sources | K9: =L9/$F$7 -> 440.8004 | L9: =SUM(L7:L8) -> 5289604.8 | N9: Net Proceeds | Q9: =SUM(Q6:Q8) -> 3977121.6 | S9: General Vacancy | V9: =Annual!K13 -> 0 | AB9: Tenant Imp Allowance | AC9: =L18 -> 100000 | AH9: General Vacancy | AI9: =V9 -> 0 | AN9: Threshold Cashflow | AO9: =AO7*AO8 -> 105792.1
B10: Leasing Summary | S10: OpEx/Property Mgmt Fee | V10: =Annual!K15 -> -18897.638 | AB10: Soft Costs (Services, Comsn) | AC10: =SUM(L22:L30,L33:L38) -> 639604.75 | AH10: OpEx/Property Mgmt Fee | AI10: =V10 -> -18897.638 | AN10: @ 100% LTC
B11: Rent Inputs | H11: Uses | N11: Base Rate (Sofr; Libor) | Q11: 0.045 | S11: Net Operating Income | V11: =SUM(V7:V10) -> 359055.12 | AB11: Total | AC11: =SUM(AC7:AC10) -> 5289604.8 | AH11: Net Operating Income | AI11: =SUM(AI7:AI10) -> 359055.12 | AN11: Meets Threshold | AO11: =IF(AI15>AO9,"YES","NO") -> NO
D12: Sq. Ft. | E12: $/RSF | F12: $ Total | H12: Land | N12: Spread | Q12: 0.02
B13: Unit 1 | D13: 12000 | E13: 30 | F13: =D13*E13 -> 360000 | H13: Land Purchase/Value | K13: =L13/$F$7 -> 166.66667 | L13: 2000000 | N13: Interest Rate | Q13: =+Q12+MAX(Q11:Q11) -> 0.065 | S13: Asset Management Fee | V13: =Annual!K19 -> -7542 | AH13: Asset Management Fee | AI13: =V13 -> -7542 | AN13: Cash on Cash | AO13: =IFERROR(V34,"NA") -> 0.022727416 | AR13: At four years, change if needed
B14: Unit 2 | D14: 0 | E14: 0 | F14: =D14*E14 -> 0 | S14: Debt Service | V14: =Q22 -> -321442.11 | AB14: Financing | AC14: $ Total | AD14: % | AH14: Debt Service | AI14: =V14 -> -321442.11
B15: Unit 3 | D15: 0 | E15: 0 | F15: =D15*E15 -> 0 | H15: Hard Costs | N15: Term | Q15: 5 | S15: Net Cashflow | V15: =V11+V14+V13 -> 30071.007 | AB15: Debt | AC15: =L7 -> 3967203.6 | AD15: =J7 -> 0.75 | AH15: Net Cashflow | AI15: =V15 -> 30071.007
B16: Unit 4 | D16: 0 | E16: 0 | F16: =D16*E16 -> 0 | H16: Site Work | K16: =L16/$F$7 -> 0 | L16: 0 | N16: Amortization | Q16: 25 | AB16: Equity | AC16: =L8 -> 1322401.2 | AD16: =J8 -> 0.25
B17: Unit 5 | D17: 0 | E17: 0 | F17: =D17*E17 -> 0 | H17: Shell & Core | K17: 200 | L17: =K17*F7 -> 2400000 | AB17: Total | AC17: =SUM(AC15:AC16) -> 5289604.8
B18: Total Rent | D18: =SUM(D13:D17) -> 12000 | E18: =F18/D18 -> 30 | F18: =SUM(F13:F17) -> 360000 | H18: Tennant Improvement Allowance | K18: =L18/$F$7 -> 8.3333333 | L18: 100000 | N18: Interest Only Period | Q18: 1 | S18: Disposition & Returns (Pre-Tax)
H19: Landscaping | K19: =L19/$F$7 -> 0 | L19: 0 | N19: Interest Only Payment | Q19: =IPMT(Q13,1,Q16,Q6) -> -230324.25 | S19: Sale Date | V19: 5
B20: Weighted Average Base Rent | E20: =SUMPRODUCT(E13:E17,D13:D17)/SUM(D13:D17) -> 30 | H20: Hard Cost Contingency | J20: 0.06 | K20: =L20/$F$7 -> 12.5 | L20: =SUM(L16:L18)*J20 -> 150000 | S20: Cost of Sale | V20: 0.015 | AB20: Debt Terms
B21: Breakeven Rent Rate | F21: =-(V14+V9+V10+V13)/F7 -> 28.990146 | H21: Soft Costs | N21: Monthly Payment | Q21: =PMT(Q13/12,Q16*12,Q6) -> -26786.843 | S21: Exit Commissions (separate take-home, not in project IRR) | V21: 0.07 | AB21: Interest Rate | AC21: =Q13 -> 0.065
H22: Architechtural | K22: =L22/$F$7 -> 0 | L22: 0 | N22: Annual Payment | Q22: =Q21*12 -> -321442.11 | S22: Exit Cap Rate | V22: 0.0625 | AB22: Term | AC22: 5
B23: Lease Term | F23: 10 | H23: Engineering | K23: =L23/$F$7 -> 0 | L23: 0 | AB23: Amortization | AC23: 25
B24: Escalation year | F24: 5 | H24: Attorney Fees | K24: =L24/$F$7 -> 0.83333333 | L24: 10000 | U24: $/RSF | V24: $ Total
B25: Escalation % | F25: 0.1 | H25: Appraisal | K25: =L25/$F$7 -> 0.58333333 | L25: 7000 | N25: Partnership Assumptions | S25: FWD NOI @ Sale | U25: =SUMIF(Annual!$J$3:$T$3,Summary!$V$19,Annual!$J$8:$T$8) -> 33 | V25: =SUMIF(Annual!$J$3:$T$3,Summary!$V$19,Annual!$J$17:$T$17) -> 394960.63
B26: Lease Type | F26: NNN | H26: Environmental | K26: =L26/$F$7 -> 0.41666667 | L26: 5000 | N26: GP Partner Name | Q26: GP
B27: NNN Recoveries | F27: 0.95 | H27: Insurance | K27: =L27/$F$7 -> 0.41666667 | L27: 5000 | S27: Gross Sale Price | U27: =V27/F7 -> 526.61417 | V27: =V25/V22 -> 6319370.1
B28: General Vacanacy | F28: 0 | H28: Utility Connect Fees | K28: =L28/$F$7 -> 1.6666667 | L28: 20000 | N28: LP Contribution Percentage | Q28: 0.9
B29: Property Management Fee | F29: 0.05 | H29: Permits and Fees | K29: =L29/$F$7 -> 0.41666667 | L29: 5000 | N29: GP Contribution Percentage | Q29: =1-Q28 -> 0.1 | S29: Equity Value | V29: =V27-Q6 -> 2352166.5
H30: Soft Cost Contingency | J30: 0.05 | K30: =L30/$F$7 -> 0.21666667 | L30: =SUM(L22:L29)*J30 -> 2600 | N30: LP Contribution Amount | Q30: =L8*Q28 -> 1190161.1
H31: Total Development Costs | K31: =L31/$F$7 -> 392.05 | L31: =SUM(L13:L30) -> 4704600 | N31: GP Contribution Amount | Q31: =L8*Q29 -> 132240.12 | S31: Levered IRR | V31: =Annual!J46 -> 0.16715309
H32: Other Soft Costs | S32: Levered EM | V32: =Annual!J47 -> 2.121005
B33: Key Assumptions | H33: Project Management during Construction | K33: =L33/$F$7 -> 1.6666667 | L33: 20000 | N33: GP Asset Management Fee | Q33: 0.02 | S33: Levered Net Profit | V33: =Annual!J48 -> 1482418.3
B34: Simple Preferred return (not compounded) | H34: Purchase Commissions (% of price) | J34: 0 | K34: =L34/$F$7 -> 0 | L34: =SUM(L7:L8)*J34 -> 0 | S34: Stabilized Cash-on-Cash Return | V34: =Annual!J50 -> 0.022727416
B35: Undistributed returns accrue | H35: Leasing Commissions (% of Term Rent) | J35: 0.07 | K35: =L35/$F$7 -> 21 | L35: =(F18*F23)*J35 -> 252000 | N35: Equity Split prior to 1st Hurdle (pari passu) | S35: Stabilized Annual Cash Flows | V35: =Annual!J51 -> 30054.762
B36: Cashflows remaining after pref return are distributed as promote | H36: Loan Origination Fee | K36: 0.01 | L36: =K36*L39 -> 47246 | N36: LP | Q36: =Q28 -> 0.9 | Y36: Annual return on total equity
B37: If GP invests, their investment treated as LP investment | H37: Loan Closing Costs | K37: 0.0075 | L37: =K37*L39 -> 35434.5 | N37: GP | Q37: =Q29 -> 0.1 | S37: LP IRR | V37: =Annual!I80 -> 0.12590104
B38: Origination fee/closing costs/commissions/interest costsduring int-only period included in loan | H38: Interest during IO period | K38: =Q18 -> 1 | L38: =-SUM(Annual!J39:T39) -> 230324.25 | N38: First Hurdle & Promote | S38: LP Equity Multiple | V38: =Annual!I81 -> 1.776804
B39: Loan closing costs include legal fees, title insurance, appraisals, recording fees | H39: Total Project Costs | K39: =L39/$F$7 -> 440.8004 | L39: =SUM(L31:L38) -> 5289604.8 | N39: Investor Preferred Annaul Return - 3rd Hurdle | Q39: 0.08 | S39: LP Net Profit | V39: =Annual!I82 -> 924521.86
N40: Promote after 3rd Hurdle | Q40: 0.2 | S40: LP Peak Capital | V40: =Annual!I83 -> 1190161.1
K41: Soft Costs | L41: =SUM(L22:L30) -> 54600
...

Sheet Annual
B3: Retail Assumptions | H3: Analysis Year | J3: 0 | K3: =+J3+1 -> 1 | L3: =+K3+1 -> 2 | M3: =+L3+1 -> 3 | N3: =+M3+1 -> 4 | O3: =+N3+1 -> 5 | P3: =+O3+1 -> 6 | Q3: =+P3+1 -> 7 | R3: =+Q3+1 -> 8 | ... T3: =+S3+1 -> 10
H4: Analysis Month | J4: 0 | K4: =+J4+12 -> 12 | L4: =+K4+12 -> 24 | M4: =+L4+12 -> 36 | N4: =+M4+12 -> 48 | O4: =+N4+12 -> 60 | P4: =+O4+12 -> 72 | Q4: =+P4+12 -> 84 | R4: =+Q4+12 -> 96 | ... T4: =+S4+12 -> 120
B5: Total Rentable Square Feet | E5: =Summary!D18 -> 12000
B6: Avg Market Rent (Today) | E6: =Summary!E18 -> 30 | H6: DEVELOPMENT COSTS | J6: =-E25 -> -5289604.8 | K6: 0 | L6: 0 | M6: 0 | N6: 0 | O6: 0 | P6: 0 | Q6: 0 | R6: 0 | S6: 0 | T6: 0
B7: Rent Escalation Year | E7: =Summary!F24 -> 5
B8: Rent Escalation Percentage | E8: =Summary!F25 -> 0.1 | H8: Market Rent /SF | K8: =+$D$11 -> 30 | L8: =IF(L3=$E$7,+K8*(1+$E$8),K8) -> 30 | M8: =IF(M3=$E$7,+L8*(1+$E$8),L8) -> 30 | N8: =IF(N3=$E$7,+M8*(1+$E$8),M8) -> 30 | O8: =IF(O3=$E$7,+N8*(1+$E$8),N8) -> 33 | P8: =IF(P3=$E$7,+O8*(1+$E$8),O8) -> 33 | Q8: =IF(Q3=$E$7,+P8*(1+$E$8),P8) -> 33 | R8: =IF(R3=$E$7,+Q8*(1+$E$8),Q8) -> 33 | S8: =IF(S3=$E$7,+R8*(1+$E$8),R8) -> 33 | T8: =IF(T3=$E$7,+S8*(1+$E$8),S8) -> 33
B10: Rent | C10: % | D10: $/SF/Yr. | E10: Total $ | H10: RETAIL CASH FLOW
B11: Base Rent (NNN) | D11: =+E6 -> 30 | E11: =+D11*E$5 -> 360000 | H11: Base Rent | K11: =+K8*$E$5 -> 360000 | L11: =+L8*$E$5 -> 360000 | M11: =+M8*$E$5 -> 360000 | N11: =+N8*$E$5 -> 360000 | O11: =+O8*$E$5 -> 396000 | P11: =+P8*$E$5 -> 396000 | Q11: =+Q8*$E$5 -> 396000 | R11: =+R8*$E$5 -> 396000 | ... T11: =+T8*$E$5 -> 396000
B12: NNN Recoveries | C12: =Summary!F27 -> 0.95 | D12: =+E12/E5 -> 1.4960626 | E12: =-C12*E15 -> 17952.756 | H12: NNN Recoveries | K12: =-K15*$C$12 -> 17952.756 | L12: =-L15*$C$12 -> 17952.756 | M12: =-M15*$C$12 -> 17952.756 | N12: =-N15*$C$12 -> 17952.756 | O12: =-O15*$C$12 -> 19748.031 | P12: =-P15*$C$12 -> 19748.031 | Q12: =-Q15*$C$12 -> 19748.031 | R12: =-R15*$C$12 -> 19748.031 | ... T12: =-T15*$C$12 -> 19748.031
B13: General Vacancy | C13: =Summary!F28 -> 0 | D13: =-C13*SUM(D11:D12) -> 0 | E13: =+D13*E$5 -> 0 | H13: General Vacancy | K13: =-SUM(K11:K12)*$C$13 -> 0 | L13: =-SUM(L11:L12)*$C$13 -> 0 | M13: =-SUM(M11:M12)*$C$13 -> 0 | N13: =-SUM(N11:N12)*$C$13 -> 0 | O13: =-SUM(O11:O12)*$C$13 -> 0 | P13: =-SUM(P11:P12)*$C$13 -> 0 | Q13: =-SUM(Q11:Q12)*$C$13 -> 0 | R13: =-SUM(R11:R12)*$C$13 -> 0 | ... T13: =-SUM(T11:T12)*$C$13 -> 0
B14: Effective Rent | D14: =SUM(D11:D13) -> 31.496063 | E14: =+D14*E$5 -> 377952.75
B15: Property Management Fee | C15: =Summary!F29 -> 0.05 | D15: =+E15/E5 -> -1.5748031 | E15: =-E14*C15 -> -18897.638 | H15: OpEx/Property Mgmt Fee | K15: =-SUM(K11:K13)*$C$15 -> -18897.638 | L15: =-SUM(L11:L13)*$C$15 -> -18897.638 | M15: =-SUM(M11:M13)*$C$15 -> -18897.638 | N15: =-SUM(N11:N13)*$C$15 -> -18897.638 | O15: =-SUM(O11:O13)*$C$15 -> -20787.402 | P15: =-SUM(P11:P13)*$C$15 -> -20787.402 | Q15: =-SUM(Q11:Q13)*$C$15 -> -20787.402 | R15: =-SUM(R11:R13)*$C$15 -> -20787.402 | ... T15: =-SUM(T11:T13)*$C$15 -> -20787.402
B16: Retail NOI | D16: =+E16/E$5 -> 29.921259 | E16: =SUM(E14:E15) -> 359055.11
B17: Asset Management Fee | C17: =Summary!Q33 -> 0.02 | D17: =+E17/E$5 -> -0.59842519 | E17: =-C17*E16 -> -7181.1023 | H17: Net Operating Income (Retail) | J17: =SUM(J11:J16) -> 0 | K17: =SUM(K11:K16) -> 359055.12 | L17: =SUM(L11:L16) -> 359055.12 | M17: =SUM(M11:M16) -> 359055.12 | N17: =SUM(N11:N16) -> 359055.12 | O17: =SUM(O11:O16) -> 394960.63 | P17: =SUM(P11:P16) -> 394960.63 | Q17: =SUM(Q11:Q16) -> 394960.63 | ... T17: =SUM(T11:T16) -> 394960.63
B18: Retail Net Income | D18: =D16+D17 -> 29.322834 | E18: =E16+E17 -> 351874.01
H19: Asset Management Fee | J19: =SUM(J11:J13)*-$C$17 -> 0 | K19: =SUM(K11:K13)*-$C$17 -> -7542 | L19: =SUM(L11:L13)*-$C$17 -> -7558.245 | M19: =SUM(M11:M13)*-$C$17 -> -7558.245 | N19: =SUM(N11:N13)*-$C$17 -> -7558.245 | O19: =SUM(O11:O13)*-$C$17 -> -8314.0695 | P19: =SUM(P11:P13)*-$C$17 -> -8314.0695 | Q19: =SUM(Q11:Q13)*-$C$17 -> -8314.0695 | ... T19: =SUM(T11:T13)*-$C$17 -> -8314.0695
B21: Acquisition Inputs | H21: Gross Sale Price | J21: =IF(J3=Summary!$V$19,+J17/Summary!$V$22,0) -> 0 | K21: =IF(K3=Summary!$V$19,+K17/Summary!$V$22,0) -> 0 | L21: =IF(L3=Summary!$V$19,+L17/Summary!$V$22,0) -> 0 | M21: =IF(M3=Summary!$V$19,+M17/Summary!$V$22,0) -> 0 | N21: =IF(N3=Summary!$V$19,+N17/Summary!$V$22,0) -> 0 | O21: =IF(O3=Summary!$V$19,+O17/Summary!$V$22,0) -> 6319407.6 | P21: =IF(P3=Summary!$V$19,+P17/Summary!$V$22,0) -> 0 | Q21: =IF(Q3=Summary!$V$19,+Q17/Summary!$V$22,0) -> 0 | ... T21: =IF(T3=Summary!$V$19,+T17/Summary!$V$22,0) -> 0
B22: Land/Building Acquisition Cost | E22: =Summary!L13 -> 2000000 | H22: Cost of Sale | J22: =J21*-Summary!$V$20 -> 0 | K22: =K21*-Summary!$V$20 -> 0 | L22: =L21*-Summary!$V$20 -> 0 | M22: =M21*-Summary!$V$20 -> 0 | N22: =N21*-Summary!$V$20 -> 0 | O22: =O21*-Summary!$V$20 -> -94791.114 | P22: =P21*-Summary!$V$20 -> 0 | Q22: =Q21*-Summary!$V$20 -> 0 | ... T22: =T21*-Summary!$V$20 -> 0
B23: Hard Cost | E23: =SUM(Summary!L16:L20) -> 2650000 | H23: Unlevered CF | J23: =+SUM(J17:J22,J6)*IF(J3>Summary!$V$19,0,1) -> -5289604.8 | K23: =+SUM(K17:K22,K6)*IF(K3>Summary!$V$19,0,1) -> 351513.12 | L23: =+SUM(L17:L22,L6)*IF(L3>Summary!$V$19,0,1) -> 351496.87 | M23: =+SUM(M17:M22,M6)*IF(M3>Summary!$V$19,0,1) -> 351496.87 | N23: =+SUM(N17:N22,N6)*IF(N3>Summary!$V$19,0,1) -> 351496.87 | O23: =+SUM(O17:O22,O6)*IF(O3>Summary!$V$19,0,1) -> 6611263 | P23: =+SUM(P17:P22,P6)*IF(P3>Summary!$V$19,0,1) -> 0 | Q23: =+SUM(Q17:Q22,Q6)*IF(Q3>Summary!$V$19,0,1) -> 0 | ... T23: =+SUM(T17:T22,T6)*IF(T3>Summary!$V$19,0,1) -> 0
B24: Soft Costs | E24: =SUM(Summary!L22:L30,Summary!L33:L38) -> 639604.75 | H24: Cumulative Unlevered CF | J24: =+J23 -> -5289604.8 | K24: =+K23+J24 -> -4938091.6 | L24: =+L23+K24 -> -4586594.8 | M24: =+M23+L24 -> -4235097.9 | N24: =+N23+M24 -> -3883601 | O24: =+O23+N24 -> 2727662 | P24: =+P23+O24 -> 2727662 | Q24: =+Q23+P24 -> 2727662 | R24: =+R23+Q24 -> 2727662 | ... T24: =+T23+S24 -> 2727662
B25: Total Project Cost | E25: =SUM(E22:E24) -> 5289604.8
B26: Total Cost / Sq Ft. | E26: =E25/E5 -> 440.8004 | H26: Unlevered IRR | J26: =IRR(J23:T23) -> 0.096691714
H27: Unlevered EM | J27: =+J28/J29+1 -> 1.5156646
B28: Debt Inputs | H28: Unlevered Net Profit | J28: =SUM(J23:T23) -> 2727662 | K28: =IF(ROUND(J28,2)<>ROUND(SUM(J23:T23),2),J28-SUM(J23:T23),"True") -> True
B29: Loan-to-Value | D29: % | E29: =Summary!J7 -> 0.75 | H29: Unlevered Peak Capital | J29: =+-MIN(J24:T24) -> 5289604.8
B30: Principle | D30: USD | E30: =E29*E25 -> 3967203.6 | F30: =IF(E30=Summary!L7,"ok","check") -> ok
B31: Interest Rate | D31: % | E31: =Summary!Q13 -> 0.065 | H31: LEVERED ANALYSIS
B32: Term | E32: =Summary!Q15 -> 5 | H32: Unlevered CF | J32: =+J23 -> -5289604.8 | K32: =+K23 -> 351513.12 | L32: =+L23 -> 351496.87 | M32: =+M23 -> 351496.87 | N32: =+N23 -> 351496.87 | O32: =+O23 -> 6611263 | P32: =+P23 -> 0 | Q32: =+Q23 -> 0 | ... T32: =+T23 -> 0
B33: Amortization (Years) | E33: =Summary!Q16 -> 25
B34: Interest Only Period | E34: =Summary!Q18 -> 1 | H34: Permanent Loan Funding | J34: =Annual!E30 -> 3967203.6 | K34: 0 | L34: 0 | M34: 0 | N34: 0 | O34: 0 | P34: 0 | Q34: 0 | R34: 0 | S34: 0 | T34: 0
H35: Loan Origination Fee | J35: =-IF(J$34>0,Summary!L36,0) -> -47246 | K35: 0 | L35: 0 | M35: 0 | N35: 0 | O35: 0 | P35: 0 | Q35: 0 | R35: 0 | S35: 0 | T35: 0
H36: Loan Closing Costs | J36: =-IF(J$34>0,Summary!L37,0) -> -35434.5 | K36: 0 | L36: 0 | M36: 0 | N36: 0 | O36: 0 | P36: 0 | Q36: 0 | R36: 0 | S36: 0 | T36: 0
B37: Equity Capital Contribution | E37: =(1-E29)*E25 -> 1322401.2 | F37: =IF(E37=Summary!L8,"ok","check") -> ok | H37: Project Management during Construction | J37: =-Summary!L33 -> -20000
F38: =IF(E37=-J60,"ok","check") -> ok | H38: Leasing Commissions (% of Term Rent) | J38: =-Summary!L35 -> -252000
H39: Interest Only Payment | J39: =IF(J3<Summary!$Q$18,Summary!$Q$19,0) -> -230324.25 | K39: =IF(K3<Summary!$Q$18,Summary!$Q$19,0) -> 0 | L39: =IF(L3<Summary!$Q$18,Summary!$Q$19,0) -> 0 | M39: =IF(M3<Summary!$Q$18,Summary!$Q$19,0) -> 0 | N39: =IF(N3<Summary!$Q$18,Summary!$Q$19,0) -> 0 | O39: =IF(O3<Summary!$Q$18,Summary!$Q$19,0) -> 0 | P39: =IF(P3<Summary!$Q$18,Summary!$Q$19,0) -> 0 | Q39: =IF(Q3<Summary!$Q$18,Summary!$Q$19,0) -> 0 | ... T39: =IF(T3<Summary!$Q$18,Summary!$Q$19,0) -> 0
H40: Amortization Payment | J40: =IF(J3>=Summary!$Q$18,Summary!$Q$22,0)*IF(J3>Summary!$V$19,0,1) -> 0 | K40: =IF(K3>=Summary!$Q$18,Summary!$Q$22,0)*IF(K3>Summary!$V$19,0,1) -> -321442.11 | L40: =IF(L3>=Summary!$Q$18,Summary!$Q$22,0)*IF(L3>Summary!$V$19,0,1) -> -321442.11 | M40: =IF(M3>=Summary!$Q$18,Summary!$Q$22,0)*IF(M3>Summary!$V$19,0,1) -> -321442.11 | N40: =IF(N3>=Summary!$Q$18,Summary!$Q$22,0)*IF(N3>Summary!$V$19,0,1) -> -321442.11 | O40: =IF(O3>=Summary!$Q$18,Summary!$Q$22,0)*IF(O3>Summary!$V$19,0,1) -> -321442.11 | P40: =IF(P3>=Summary!$Q$18,Summary!$Q$22,0)*IF(P3>Summary!$V$19,0,1) -> 0 | Q40: =IF(Q3>=Summary!$Q$18,Summary!$Q$22,0)*IF(Q3>Summary!$V$19,0,1) -> 0 | ... T40: =IF(T3>=Summary!$Q$18,Summary!$Q$22,0)*IF(T3>Summary!$V$19,0,1) -> 0
H41: Repayment | K41: =K117 -> 0 | L41: =L117 -> 0 | M41: =M117 -> 0 | N41: =N117 -> 0 | O41: =O117 -> -3605236.7 | P41: =P117 -> 0 | Q41: =Q117 -> 0 | R41: =R117 -> 0 | ... T41: =T117 -> 0
G43: Does not Include the soft costs because | H43: Levered FCF | J43: =+SUM(J32:J34) -> -1322401.2 | K43: =+SUM(K32:K41) -> 30071.007 | L43: =+SUM(L32:L41) -> 30054.762 | M43: =+SUM(M32:M41) -> 30054.762 | N43: =+SUM(N32:N41) -> 30054.762 | O43: =+SUM(O32:O41) -> 2684584.2 | P43: =+SUM(P32:P41) -> 0 | Q43: =+SUM(Q32:Q41) -> 0 | R43: =+SUM(R32:R41) -> 0 | ... T43: =+SUM(T32:T41) -> 0
G44: All soft Costs in year 1 net out to zero due to loan funding and equity contribution | H44: Cumulative Levered CF | J44: =+J43 -> -1322401.2 | K44: =+K43+J44 -> -1292330.2 | L44: =+L43+K44 -> -1262275.4 | M44: =+M43+L44 -> -1232220.7 | N44: =+N43+M44 -> -1202165.9 | O44: =+O43+N44 -> 1482418.3 | P44: =+P43+O44 -> 1482418.3 | Q44: =+Q43+P44 -> 1482418.3 | R44: =+R43+Q44 -> 1482418.3 | ... T44: =+T43+S44 -> 1482418.3
H46: Levered IRR | J46: =IRR(J43:T43) -> 0.16715309
...

Sheet Seminole Dev Inputs
A1: 6968 SEMINOLE TRAIL — Goodwill Build-to-Suit (RETAIL ONLY)
A2: Ruckersville (Greene County), VA | Parcels 66-A-45 & 66-A-46 | Self-storage removed — see Phase 2 note. Blue = input.
A4: SITE & LAND
A5: Land Cost (total) | B5: 1250000
A6: Broker asking ($/acre) | B6: 1475000
A7: Assemblage acreage (survey) | B7: 5.04
A8: Implied land at asking (full site) | B8: =B6*B7 -> 7434000
A9: 2023 assessed value (66-A-46) | B9: 796500
A10: Implied land $/acre (at land cost) | B10: =B5/B7 -> 248015.87
A11: Zoning: currently R-1/R-2 — requires B-3 rezoning
A13: RETAIL PAD (Goodwill build-to-suit)
A14: Retail Size (SF) | B14: 6000
A15: Retail Rent ($/SF/yr, NNN) | B15: 28
A16: Retail Construction Cost ($/SF) | B16: 120
A17: Retail Vacancy / credit loss (%) | B17: 0
A19: DEVELOPMENT COSTS
A20: Soft Cost (% of construction) | B20: 0.15
A22: FINANCING
A23: Loan-to-Cost (LTC) | B23: 0.7
A24: Interest Rate | B24: 0.0725
A25: Amortization (years) | B25: 30
A26: Hold Period (years) | B26: 5
A28: EXIT
A29: Exit Cap Rate | B29: 0.075
A30: Cost of Sale (%) | B30: 0.02
A32: USES
A33: Land | B33: =B5 -> 1250000
A34: Retail Construction | B34: =B14*B16 -> 720000
A35: Hard Cost Subtotal | B35: =B34 -> 720000
A36: Soft Costs | B36: =B35*B20 -> 108000
A37: Total Project Cost | B37: =B33+B35+B36 -> 2078000
A39: SOURCES
A40: Debt (LTC) | B40: =B37*B23 -> 1454600
A41: Equity | B41: =B37-B40 -> 623400
A42: Total Sources | B42: =B40+B41 -> 2078000
A43: Check (Sources = Uses) | B43: =IF(ABS(B42-B37)<1,"OK","CHECK") -> OK
A45: PHASE 2 (OPTIONAL — NOT IN THESE ECONOMICS)
A46: Self-storage could be added on the rear land in a later phase. Reference-only figures below; excluded from all totals.
A47: Ref: Storage Gross SF | B47: 65000
A48: Ref: Storage Cost ($/SF) | B48: 92
...

Sheet Seminole Dev Returns
A1: 6968 SEMINOLE TRAIL — NOI & Returns (Goodwill BTS, RETAIL ONLY, stabilized)
A3: RETAIL (Goodwill BTS, NNN)
A4: Potential Rent | B4: ='Seminole Dev Inputs'!B14*'Seminole Dev Inputs'!B15 -> 168000
A5: Less: Vacancy / credit loss | B5: =-B4*'Seminole Dev Inputs'!B17 -> 0
A6: Retail NOI | B6: =B4+B5 -> 168000
A8: TOTAL
A9: Total Stabilized NOI | B9: =B6 -> 168000
A11: DEVELOPMENT RETURN
A12: Total Project Cost | B12: ='Seminole Dev Inputs'!B37 -> 2078000
A13: Total Stabilized NOI | B13: =B9 -> 168000
A14: Yield on Cost | B14: =B13/B12 -> 0.080846968
A15: Exit Cap Rate | B15: ='Seminole Dev Inputs'!B29 -> 0.075
A16: Development Spread | B16: =B14-B15 -> 0.0058469682
A18: EXIT / PROFIT
A19: Exit Value (NOI / Exit Cap) | B19: =B13/B15 -> 2240000
A20: Less: Cost of Sale | B20: =-B19*'Seminole Dev Inputs'!B30 -> -44800
A21: Net Sale Value | B21: =B19+B20 -> 2195200
A22: Development Profit (net) | B22: =B21-B12 -> 117200
A23: Profit Margin on Cost | B23: =B22/B12 -> 0.056400385
A25: FINANCING & CASH FLOW
A26: Loan Amount | B26: ='Seminole Dev Inputs'!B40 -> 1454600
A27: Equity | B27: ='Seminole Dev Inputs'!B41 -> 623400
A28: Annual Debt Service | B28: =-PMT('Seminole Dev Inputs'!B24,'Seminole Dev Inputs'!B25,B26) -> 120178.5
A29: DSCR | B29: =B13/B28 -> 1.3979206
A30: Stabilized Cash Flow (after DS) | B30: =B13-B28 -> 47821.502
A31: Cash-on-Cash | B31: =B30/B27 -> 0.076710783
A33: DEBT SCHEDULE (annual)
D34: Year | E34: Beg Balance | F34: Debt Service | G34: Interest | H34: Principal | I34: End Balance
D35: 0 | I35: =B26 -> 1454600
D36: 1 | E36: =I35 -> 1454600 | F36: =$B$28 -> 120178.5 | G36: =E36*'Seminole Dev Inputs'!$B$24 -> 105458.5 | H36: =F36-G36 -> 14719.998 | I36: =E36-H36 -> 1439880
D37: 2 | E37: =I36 -> 1439880 | F37: =$B$28 -> 120178.5 | G37: =E37*'Seminole Dev Inputs'!$B$24 -> 104391.3 | H37: =F37-G37 -> 15787.198 | I37: =E37-H37 -> 1424092.8
D38: 3 | E38: =I37 -> 1424092.8 | F38: =$B$28 -> 120178.5 | G38: =E38*'Seminole Dev Inputs'!$B$24 -> 103246.73 | H38: =F38-G38 -> 16931.769 | I38: =E38-H38 -> 1407161
D39: 4 | E39: =I38 -> 1407161 | F39: =$B$28 -> 120178.5 | G39: =E39*'Seminole Dev Inputs'!$B$24 -> 102019.18 | H39: =F39-G39 -> 18159.323 | I39: =E39-H39 -> 1389001.7
D40: 5 | E40: =I39 -> 1389001.7 | F40: =$B$28 -> 120178.5 | G40: =E40*'Seminole Dev Inputs'!$B$24 -> 100702.62 | H40: =F40-G40 -> 19475.874 | I40: =E40-H40 -> 1369525.8
A41: Loan Balance at Exit | B41: =I40 -> 1369525.8
A43: LEVERED RETURN (stabilized hold)
A44: Net Sale Proceeds to Equity | B44: =B21-B41 -> 825674.16
A45: Levered Cash Flows | D45: =-B27 -> -623400 | E45: =$B$30 -> 47821.502 | F45: =$B$30 -> 47821.502 | G45: =$B$30 -> 47821.502 | H45: =$B$30 -> 47821.502 | I45: =$B$30+$B$44 -> 873495.66
A46: Levered IRR | B46: =IRR(D45:I45) -> 0.12707291
A47: Equity Multiple | B47: =(B30*'Seminole Dev Inputs'!B26+B44)/B27 -> 1.7080232
...
